Workbook

Sheet Дог.
A4: ='Пр №1'!B20 -> {{TOOL_NAME}} | D4: ='Пр №1'!J20 -> 45982.791 | F4: ='Пр №1'!L20 -> 45982.791 | H4: ='Пр №1'!P30 -> 3000
D5: ='Пр №1'!J21 -> 45982 | F5: ='Пр №1'!L21 -> 45983
B7: Телефон: | D7: {{CLIENT_PHONE}} | K7: Телефон: | M7: =D7
G8: Филиал № | J8: 1 | L8: ул. Лермонтова д.№ 68
A9: Договор аренды оборудования (имущественного найма) | R9: {=IFERROR(VLOOKUP(TRIM("*"&A18&"*"),TRIM(_xlfn.SINGLE('[1]Умная таблица'!$A$1:$G$1057)),4,FALSE),"Нет данных")} -> Нет данных | S9: {=IFERROR(MATCH(TRIM("*"&A18&"*"),TRIM('[1]Умная таблица'!$A:$A),0),"Нет данных")} -> Нет данных
I10: № | J10: =J13 -> 21 | K10: =MONTH(L13&11) -> 11 | L10: =N13 -> 2025 | M10: =D4 -> 45982.791 | N10: =J8 -> 1 | P10: версия : 24.01.2025
P11: =+TODAY() -> 45982
A12: {{TOOL_NAME}} | R12: {=IFERROR(VLOOKUP(TRIM(A18),TRIM('[1]Умная таблица'!$A$1:$G$1057),4,FALSE),"Нет данных")} -> Нет данных | S12: {=IFERROR(MATCH(TRIM(A18),TRIM('[1]Умная таблица'!$A:$A),0),"Нет данных")} -> Нет данных
B13: г. Бишкек | I13: « | J13: =DAY(TODAY()) -> 21 | K13: » | L13: =TEXT(P11,"ММММ") -> Ноябрь | N13: =YEAR(TODAY()) -> 2025 | O13: г.
A14: Зинченко Михаил Александрович | G14: 22.12.2006 года рождения, паспорт: ID3219844 выдан MKK 218011от 12.02.2023 г.
A15: зарегистрированный по адресу город Бишкек, улица Ялтинская 56/1, действующий на основании Свидетельства о государственной
A16: регистрации индивидуального предпринимателя по Свердловскому району г. Бишкек № 003-2024-169-5930 от 08.08.2024
A17: ИНН: | C17: 22212200650516 | H17: именуемый в дальнейшем «Арендодатель», с одной стороны и
A18: {{CLIENT_FULLNAME}} | I18: именуемый(-ая) в дальнейшем «Арендатор», действующий(-ая)
A19: на основании паспорта: | E19: ХХХ | F19: № | G19: ХХХХХ | I19: выдан | J19: МКК | K19: ХХХХ | L19: от | M19: ХХХХ | N19: зарегистрированный(-ая)
A20: по адресу: | C20: Чуйская область г. Бишкек | J20: ул. ХХХХХ | N20: Факт. место проживания
A21: =C20 -> Чуйская область г. Бишкек | I21: =J20 -> ул. ХХХХХ
A22: ПИН: | C22: ХХХХ | G22: Адрес объекта:
A23: ХХХХХ | C23: года рождения | F23: с другой стороны заключили Договор о нижеследующем:
A24: 1. ПРЕДМЕТ ДОГОВОРА
A25: 1.1. Арендодатель обязуется передать во временное пользование инструменты, машины и другое оборудование для выполнения
A26: строительных работ, именуемое в дальнейшем «Имущество», а Арендатор в свою очередь обязуется оплатить арендную плату за
A27: пользование Имуществом Арендодателю, а также вернуть ему оборудование в порядке и сроки, указанные в Приложении №1
A28: к настоящему Договору.
A29: 1.2. Арендодатель и Арендатор определяют: наименование переданного Имущества, дату и время выдачи, дату и время возврата,
A30: стоимость арендной оплаты, сумму обеспечительного платежа и место возврата Имущества, в приложении №1 к договору.
A31: 1.3. Имущество, предоставляемое в аренду по настоящему Договору, должно использоваться по прямому назначению в
A32: соответствии с Правилами аренды строительного инструмента.
A33: 1.4. Арендатор ознакомлен, Арендодателем, с правилами эксплуатации и хранения Имущества, соблюдением правил техники
A34: безопасности.
A35: 2. ПРАВА И ОБЯЗАННОСТИ СТОРОН
... A60: питания, утраты защитных элементов, появления посторонних звуков в работе и других проявлений неисправности.
A61: , - в случае поломки имущества, известить по номеру | J61: =M7 -> =D7 | M61: и сдать Имущество в течение 1-х суток с
A62: момента поломки в пункт выдачи для выяснения причин поломки;
A63: ,- эксплуатировать полученное Имущество в соответствии с правилами его эксплуатации и техническими
A64: характеристиками, соблюдая технику безопасности;
A67: =TRIM(SUBSTITUTE(LEFT(A14&" ",SEARCH(" ",A14&" ")+1)&"."& MID(A14&" ",SEARCH(" ",A14&" ",SEARCH(" ",A14&" ")+1),2)&"."," .",)) -> Зинченко М. А. | D67: ____________________________ | K67: =TRIM(SUBSTITUTE(LEFT(A18&" ",SEARCH(" ",A18&" ")+1)&"."& MID(A18&" ",SEARCH(" ",A18&" ",SEARCH(" ",A18&" ")+1),2)&"."," .",)) -> #VALUE! | N67: _________________________
D68: (подпись) | N68: (подпись)
J70: ____________________________________________________
K71: (Расшифровка подписи)
...

Sheet Пр №1
A2: Приложение №1 к Договору аренды оборудования
I3: =Дог.!I10 -> № | J3: =Дог.!J10 -> 21 | K3: =Дог.!K10 -> 11 | L3: =Дог.!L10 -> 2025 | M3: =Дог.!M10 -> 45982.791 | N3: =Дог.!N10 -> 1
B5: г. Бишкек | I5: « | J5: =Дог.!J13 -> 21 | K5: » | L5: =Дог.!L13 -> Ноябрь | N5: =Дог.!N13 -> 2025 | O5: г.
A6: =Дог.!A14 -> Зинченко Михаил Александрович | G6: =Дог.!G14 -> 22.12.2006 года рождения, паспорт: ID3219844 выдан MKK 218011от 12.02.2023 г.
A7: =Дог.!A15 -> зарегистрированный по адресу город Бишкек, улица Ялтинская 56/1, действующий на основании Свидетельства о государственной
A8: =Дог.!A16 -> регистрации индивидуального предпринимателя по Свердловскому району г. Бишкек № 003-2024-169-5930 от 08.08.2024
A9: =Дог.!A17 -> ИНН: | C9: =Дог.!C17 -> 22212200650516 | H9: именуемый в дальнейшем «Арендодатель», с одной стороны и
A10: =Дог.!A18 -> {{CLIENT_FULLNAME}} | I10: именуемый(-ая) в дальнейшем «Арендатор», действующий(-ая)
A11: =Дог.!A19 -> на основании паспорта: | E11: =Дог.!E19 -> ХХХ | F11: =Дог.!F19 -> № | G11: =Дог.!G19 -> ХХХХХ | I11: =Дог.!I19 -> выдан | J11: =Дог.!J19 -> МКК | K11: =Дог.!K19 -> ХХХХ | L11: =Дог.!L19 -> от | M11: =Дог.!M19 -> ХХХХ | N11: =Дог.!N19 -> зарегистрированный(-ая)
A12: по адресу: | C12: =Дог.!C20 -> Чуйская область г. Бишкек | I12: =Дог.!J20 -> ул. ХХХХХ | N12: Факт. место проживания
A13: =Дог.!A21 -> Чуйская область г. Бишкек | H13: =Дог.!I21 -> ул. ХХХХХ
A14: ПИН: | C14: =Дог.!C22 -> ХХХХ | G14: Адрес объекта: | K14: =Дог.!K22 -> 0
A15: с другой стороны, а вместе именуемые «Стороны», составили настоящее приложение в соответствии с Договором
A16: аренды оборудования | E16: № | F16: =J3 -> 21 | G16: =K3 -> 11 | H16: =L3 -> 2025 | I16: =M3 -> 45982.791 | J16: =N3 -> 1 | K16: о нижеследующем:
A17: 1. В соответствии с пунктом 1.2. Договора аренды оборудования | K17: № | L17: =F16 -> 21 | M17: =G16 -> 11 | N17: =H16 -> 2025 | O17: =I16 -> 45982.791 | P17: =N3 -> 1 | Q17: Арендодатель
A18: передает Арендатору следующее имущество и вместе они определили (оговорили) стоимость арендной оплаты и сроки возврата Имущества:
A19: № | B19: Наименование Имущества | F19: Фактическая стоимость проката | G19: Дата и время фактического возврата Имущества | I19: Кол-во | J19: Дата и время выдачи Имущества | L19: Оговоренная дата и время возврата Имущества | N19: Стоимость аренды (найма) Имущества за 1 сутки | P19: Сумма обеспечительного платежа
A20: 1 | B20: =Дог.!A12 -> {{TOOL_NAME}} | I20: 1 | J20: =NOW() -> 45982.791 | L20: =J20 -> 45982.791 | N20: 1500 | P20: =I20*3000 -> 3000
J21: =DATE(L3,K3,J3) -> 45982 | L21: =J21+1 -> 45983
A22: 2 | J22: =IF(LEN(B22),J20,"") | L22: =J22
J23: =IF(LEN(B22),J21,"") | L23: =IF(LEN(B22),L21,"")
A24: 3 | J24: =IF(LEN(B24),J20,"") | L24: =J24 | P24: =I24*3000 -> 0
J25: =IF(LEN(B24),J21,"") | L25: =IF(LEN(B24),L21,"")
A26: 4 | J26: =IF(LEN(B26),J20,"") | L26: =J26 | P26: =I26*3000 -> 0
J27: =IF(LEN(B26),J21,"") | L27: =IF(LEN(B26),L21,"")
A28: 5 | J28: =IF(LEN(B28),J20,"") | L28: =J28 | P28: =I28*3000 -> 0
J29: =IF(LEN(B28),J21,"") | L29: =IF(LEN(B28),L21,"")
N30: Итого: | P30: =SUM(P20:Q29) -> 3000
A31: 2. Оговоренный срок возврата и арендной оплаты за пользование Имуществом | K31: =L20 -> 45982.791 | M31: =L21 -> 45983 | O31: В залоге | P31: паспорт
A32: 3. Арендатор обязуется оплатить арендную плату за пользование Имуществом, не позднее 5 (пяти) рабочих | O32: Предоплата
A33: дней с момента возврата Имущества Арендодателю. (согласно пункту 3.6. договора аренды оборудования) | O33: Дата | Q33: Сумма
A34: =IF(LEN(P31),N34,"") -> 4. Арендатор добровольно передает личный паспорт гражданина в залог за арендуемое оборудование. | N34: 4. Арендатор добровольно передает личный паспорт гражданина в залог за арендуемое оборудование.
A35: 5. Исправность имущества, сдаваемого в аренду проверена Арендодателем в присутствии Арендатора.
A36: 6. Имущество передается Арендатору и возвращается по месту нахождения пункта проката Арендодателя
D37: Пункт проката : | H37: =Дог.!L8 -> ул. Лермонтова д.№ 68
A38: Арендная оплата и обеспечительный платеж .
A39: 1. Обеспечительный платеж взимается на момент заключения настоящего приложения, путем передачи наличными денежных средств,
A40: Арендатором Арендодателю или путем перечисления суммы на расчетный счет Арендодателя.
A41: 2. В случае досрочного возврата имущества Арендатору возвращается сумма за неиспользованное время проката Имущества.
A42: 3. Арендатор предоставляет Арендодателю обеспечительный платеж в размере | M42: =P30 -> 3000 | O42: При этом в случае
...

Sheet Акт прием
A3: АКТ ПРИЕМА-ПЕРЕДАЧИ ИМУЩЕСТВА В ПРОКАТ
A4: к Договору аренды оборудования
J5: № | K5: ='Пр №1'!J3 -> 21 | L5: ='Пр №1'!K3 -> 11 | M5: ='Пр №1'!L3 -> 2025 | N5: ='Пр №1'!M3 -> 45982.791 | O5: ='Пр №1'!N3 -> 1
B6: =Дог.!B13 -> г. Бишкек | I6: ='Пр №1'!I5 -> « | J6: ='Пр №1'!J5 -> 21 | K6: ='Пр №1'!K5 -> » | L6: ='Пр №1'!L5 -> Ноябрь | N6: ='Пр №1'!N5 -> 2025 | O6: ='Пр №1'!O5 -> г.
A7: ='Пр №1'!A6:E6 -> Зинченко Михаил Александрович | G7: ='Пр №1'!G6:Q6 -> 22.12.2006 года рождения, паспорт: ID3219844 выдан MKK 218011от 12.02.2023 г.
A8: ='Пр №1'!A7:Q7 -> зарегистрированный по адресу город Бишкек, улица Ялтинская 56/1, действующий на основании Свидетельства о государственной
A9: ='Пр №1'!A8:Q8 -> регистрации индивидуального предпринимателя по Свердловскому району г. Бишкек № 003-2024-169-5930 от 08.08.2024
A10: ='Пр №1'!A9:G9 -> ИНН: | C10: ='Пр №1'!C9:G9 -> 22212200650516 | H10: именуемый в дальнейшем «Арендодатель», с одной стороны и
A11: =Дог.!A18 -> {{CLIENT_FULLNAME}} | I11: именуемый(-ая) в дальнейшем «Арендатор», действующий(-ая)
A12: =Дог.!A19 -> на основании паспорта: | E12: =Дог.!E19 -> ХХХ | F12: =Дог.!F19 -> № | G12: =Дог.!G19 -> ХХХХХ | I12: =Дог.!I19 -> выдан | J12: =Дог.!J19 -> МКК | K12: ='Пр №1'!K11 -> ХХХХ | L12: ='Пр №1'!L11 -> от | M12: ='Пр №1'!M11 -> ХХХХ | N12: =Дог.!N19 -> зарегистрированный(-ая)
A13: по адресу: | C13: ='Пр №1'!C12:G12 -> Чуйская область г. Бишкек | I13: ='Пр №1'!I12:M12 -> ул. ХХХХХ | N13: Факт. место проживания
A14: ='Пр №1'!A13:E13 -> Чуйская область г. Бишкек | H14: ='Пр №1'!H13:Q13 -> ул. ХХХХХ
A15: ПИН: | C15: ='Пр №1'!C14:F14 -> ХХХХ | G15: Адрес объекта: | K15: ='Пр №1'!K14:P14 -> 0
A16: с другой стороны, а вместе именуемые «Стороны», заключили настоящий акт к Договору
A17: аренды оборудования | E17: № | F17: =K5 -> 21 | G17: =L5 -> 11 | H17: =M5 -> 2025 | I17: =N5 -> 45982.791 | J17: =O5 -> 1 | K17: о нижеследующем:
A18: 1. Во исполнение Договора аренды оборудования | J18: № | K18: =K5 -> 21 | L18: =L5 -> 11 | M18: =M5 -> 2025 | N18: =N5 -> 45982.791 | O18: =O5 -> 1
A19: Арендодатель передал Арендатору следующее Имущество:
A20: № | B20: Наименование Имущества | J20: Кол-Во | L20: Завод. или индеф. № | N20: Стоимость оборудования
A21: ='Пр №1'!A20 -> 1 | B21: ='Пр №1'!B20 -> {{TOOL_NAME}} | J21: ='Пр №1'!I20 -> 1 | L21: 112 | N21: =35000*J21 -> 35000
A22: 2 | B22: ='Пр №1'!B22 -> 0 | J22: ='Пр №1'!I22 -> 0 | N22: =35000*J22 -> 0
A23: 3 | B23: ='Пр №1'!B24 -> 0 | J23: ='Пр №1'!I24 -> 0 | N23: =35000*J23 -> 0
A24: 4 | B24: ='Пр №1'!B26 -> 0 | J24: ='Пр №1'!I26 -> 0 | N24: =35000*J24 -> 0
A25: 5 | B25: ='Пр №1'!B28 -> 0 | J25: ='Пр №1'!I28 -> 0 | N25: =35000*J25 -> 0
A26: Итого: стоимость оборудования | N26: =SUM(N21:Q25) -> 35000
A27: 2. Имущество передается в полной исправности. Работоспособность Имущества проверена в присутствии Арендатора
A28: 3. Арендодатель ознакомил Арендатора с правилами эксплуатации и хранения Имущества, с правилами техники безопасности.
A29: 4. Настоящим Арендодатель подтверждает получение от Арендатора суммы обеспечительного платежа в размере | O29: ='Пр №1'!P30 -> 3000
A30: 5. Настоящий Акт составлен в 2-ух экземплярах, имеющих одинаковую юридическую силу, по одному для каждой из сторон.
A33: 8. РЕКВИЗИТЫ СТОРОН
A34: АРЕНДОДАТЕЛЬ: | J34: АРЕНДАТОР:
A35: Ф.И.О.: | B35: ='Пр №1'!B50:G50 -> Зинченко Михаил Александрович | J35: ='Пр №1'!J50:K50 -> Ф.И.О.: | L35: ='Пр №1'!L50:Q50 -> {{CLIENT_FULLNAME}}
A36: ИНН: | B36: ='Пр №1'!B51:G51 -> 22212200650516 | J36: ='Пр №1'!J51:K51 -> ПИН: | L36: ='Пр №1'!L51:P51 -> ХХХХ
A37: Паспорт: | C37: ='Пр №1'!C52 -> ID | D37: № | E37: ='Пр №1'!E52:G52 -> 1706490 | J37: ='Пр №1'!J52:K52 -> Паспорт: | L37: ='Пр №1'!L52 -> ХХХ | M37: № | N37: ='Пр №1'!N52:O52 -> ХХХХХ
A38: Выдан: | C38: ='Пр №1'!C53:G53 -> МКК 211041 от 05.06.2020 | J38: ='Пр №1'!J53:K53 -> Выдан: | L38: ='Пр №1'!L53 -> МКК | M38: ='Пр №1'!M53 -> ХХХХ | N38: ='Пр №1'!N53 -> от | O38: ='Пр №1'!O53 -> ХХХХ
A39: Адрес: | C39: ='Пр №1'!C54:G54 -> г. Бишкек | J39: ='Пр №1'!J54:K54 -> Адрес: | L39: ='Пр №1'!L54:Q54 -> Чуйская область г. Бишкек
A40: ='Пр №1'!A55:G55 -> ул. Ялтинская д. № 56 | J40: ='Пр №1'!J55:P55 -> ул. ХХХХХ
A41: Почтовый индекс: | D41: ='Пр №1'!D56:G56 -> 720051 | J41: ='Пр №1'!J56:L56 -> Почтовый индекс: | M41: ='Пр №1'!M56:N56 -> 0
A42: Банковские реквизиты: | J42: ='Пр №1'!J57:P57 -> Банковские реквизиты:
A43: ='Пр №1'!A58:G58 -> ОАО Комерческий банк Кыргызстан | J43: ='Пр №1'!J58:P58 -> 0
A44: р/c: | B44: ='Пр №1'!B59:G59 -> "1030120300369929" | J44: ='Пр №1'!J59 -> р/c: | K44: ='Пр №1'!K59:P59 -> 0
...

Sheet Акт расч
A3: АКТ РАСЧЕТА АРЕНДНОЙ ПЛАТЫ
A4: к Договору аренды оборудования
J5: № | K5: ='Пр №1'!J3 -> 21 | L5: ='Пр №1'!K3 -> 11 | M5: ='Пр №1'!L3 -> 2025 | N5: ='Пр №1'!M3 -> 45982.791 | O5: ='Акт прием'!O5 -> 1
B6: =Дог.!B13 -> г. Бишкек | I6: ='Пр №1'!I5 -> « | J6: ='Пр №1'!J5 -> 21 | K6: ='Пр №1'!K5 -> » | L6: ='Пр №1'!L5 -> Ноябрь | N6: ='Пр №1'!N5 -> 2025 | O6: ='Пр №1'!O5 -> г.
A7: ='Акт прием'!A7:E7 -> Зинченко Михаил Александрович | G7: ='Акт прием'!G7:Q7 -> 22.12.2006 года рождения, паспорт: ID3219844 выдан MKK 218011от 12.02.2023 г.
A8: ='Пр №1'!A7:Q7 -> зарегистрированный по адресу город Бишкек, улица Ялтинская 56/1, действующий на основании Свидетельства о государственной
A9: ='Пр №1'!A8:Q8 -> регистрации индивидуального предпринимателя по Свердловскому району г. Бишкек № 003-2024-169-5930 от 08.08.2024
A10: ='Акт прием'!A10:G10 -> ИНН: | C10: ='Пр №1'!C9:G9 -> 22212200650516 | H10: именуемый в дальнейшем «Арендодатель», с одной стороны и
A11: =Дог.!A18 -> {{CLIENT_FULLNAME}} | I11: именуемый(-ая) в дальнейшем «Арендатор», действующий(-ая)
A12: =Дог.!A19 -> на основании паспорта: | E12: =Дог.!E19 -> ХХХ | F12: =Дог.!F19 -> № | G12: =Дог.!G19 -> ХХХХХ | I12: =Дог.!I19 -> выдан | J12: =Дог.!J19 -> МКК | K12: ='Пр №1'!K11 -> ХХХХ | L12: ='Пр №1'!L11 -> от | M12: ='Пр №1'!M11 -> ХХХХ | N12: =Дог.!N19 -> зарегистрированный(-ая)
A13: по адресу: | C13: ='Акт прием'!C13:G13 -> Чуйская область г. Бишкек | I13: ='Акт прием'!I13:M13 -> ул. ХХХХХ | N13: Факт. место проживания
A14: ='Акт прием'!A14:E14 -> Чуйская область г. Бишкек | H14: ='Пр №1'!H13:Q13 -> ул. ХХХХХ
A15: ПИН: | C15: ='Пр №1'!C14:F14 -> ХХХХ | G15: Адрес объекта: | K15: ='Пр №1'!K14:P14 -> 0
A16: с другой стороны, а вместе именуемые «Стороны», заключили настоящий акт к Договору аренды оборудования о нижеследующем:
A17: 1. Во исполнение Договора аренды оборудования | J17: № | K17: =K5 -> 21 | L17: =L5 -> 11 | M17: =M5 -> 2025 | N17: =N5 -> 45982.791 | O17: =O5 -> 1
A18: Арендатор возвращает, а Арендодатель принимает следующее Имущество и рассчитывает арендную плату за пользование оборудованием:
A19: № | B19: Наименование Имущества | F19: ='Пр №1'!J19 -> Дата и время выдачи Имущества | G19: ='Акт возв'!J20 -> Дата и время возврата | H19: Расчетный период аренды | J19: Количество оборудования | L19: Кол. Суток | M19: Ед.Изм. | N19: Цена в сутки | P19: Сумма сом
A20: 1 | B20: ='Пр №1'!B20 -> {{TOOL_NAME}} | F20: ='Пр №1'!J20 -> 45982.791 | H20: ='Пр №1'!J20 -> 45982.791 | J20: ='Пр №1'!I20 -> 1 | L20: =H21-F21 -> 0 | M20: Сут | N20: ='Пр №1'!N20 -> 1500 | P20: =J20*L20*N20 -> 0
F21: ='Пр №1'!J21 -> 45982 | H21: ='Пр №1'!J21 -> 45982
A22: 2 | B22: ='Пр №1'!B22:E23 -> 0 | J22: ='Пр №1'!I22 -> 0 | L22: =H23-F23 -> 0 | P22: =J22*L22*N22 -> 0
A24: 3 | B24: ='Пр №1'!B24:E25 -> 0 | J24: ='Пр №1'!I24 -> 0 | L24: =H25-F25 -> 0 | P24: =J24*L24*N24 -> 0
A26: 4 | B26: ='Пр №1'!B26:E27 -> 0 | J26: ='Пр №1'!I26 -> 0 | L26: =H27-F27 -> 0 | P26: =J26*L26*N26 -> 0
A28: 5 | B28: ='Пр №1'!B28:E29 -> 0 | J28: ='Пр №1'!I28 -> 0 | L28: =H29-F29 -> 0 | P28: =J28*L28*N28 -> 0
A30: 6 | L30: =H31-F31 -> 0 | P30: =J30*L30*N30 -> 0
A32: 7 | L32: =H33-F33 -> 0 | P32: =J32*L32*N32 -> 0
A34: 8 | L34: =H35-F35 -> 0 | P34: =J34*L34*N34 -> 0
A36: 9 | L36: =H37-F37 -> 0 | P36: =J36*L36*N36 -> 0
A38: 10 | L38: =H39-F39 -> 0 | P38: =J38*L38*N38 -> 0
J40: Дата Сегодня: | M40: ='Пр №1'!J21 -> 45982 | N40: Всего: | P40: =SUM(P20:Q39) -> 0
J41: Дата Обязательство: | M41: =Обяз!K22 -> 45985 | N41: Депозит: | P41: ='Пр №1'!P30:Q30 -> 3000
A42: № | B42: Расчет неустоек | L42: Ед. Изм. | N42: Кол. Суток
A43: 1 | B43: Количество суток просрочки невозврата Имущества | L43: Сегодня: | N43: ='Пр №1'!J21 -> 45982
A44: 2 | B44: Согласно пункту 2.8. Неустойка 1% за каждые сутки просрочки не возврата Имущества | L44: Сутки | P44: ='Акт прием'!N21*1%*N44 -> 0
A45: 3 | B45: Количество суток просрочки арендного платежа | L45: Обязательство: | N45: =Обяз!K22 -> 45985
A46: 4 | B46: Согласно пункту 3.6. Неустойка 1% за каждые сутки просрочки арендного платежа | L46: Сутки | P46: ='Акт прием'!N21*1%*N46 -> 0
A47: 5 | B47: Неустойка по ОБЯЗАТЕЛЬСТВУ 1 (один) % от оставшейся суммы общего долга в день | L47: Сумма долга | P47: =(P40-P41)*1%*N47 -> 0
B48: Итого к оплате: | P48: =P40-P41+P44+P46+P47 -> -3000
A49: 2. Имущество передается в полной исправности. Работоспособность Имущества проверена Арендодателем
A50: 3. Настоящим Арендодатель подтверждает получение предоплаты в размере | M50: =P41 -> 3000 | P50: от Арендатора.
A51: 4. Арендатор обязуется оплатить образовавшуюся задолженность в размере | J51: =P48 -> -3000 | M51: не позднее 5 (пяти) рабочих дней с момента
...

Sheet Акт возв
A3: АКТ ВОЗВРАТА ИМУЩЕСТВА
A4: к Договору аренды оборудования
J5: № | K5: ='Пр №1'!J3 -> 21 | L5: ='Пр №1'!K3 -> 11 | M5: ='Пр №1'!L3 -> 2025 | N5: ='Пр №1'!M3 -> 45982.791 | O5: ='Акт расч'!O5 -> 1
B6: =Дог.!B13 -> г. Бишкек | I6: ='Пр №1'!I5 -> « | J6: ='Пр №1'!J5 -> 21 | K6: ='Пр №1'!K5 -> » | L6: ='Пр №1'!L5 -> Ноябрь | N6: ='Пр №1'!N5 -> 2025 | O6: ='Пр №1'!O5 -> г.
A7: ='Акт расч'!A7:E7 -> Зинченко Михаил Александрович | G7: ='Счет '!G7:Q7 -> 22.12.2006 года рождения, паспорт: ID3219844 выдан MKK 218011от 12.02.2023 г.
A8: ='Пр №1'!A7:Q7 -> зарегистрированный по адресу город Бишкек, улица Ялтинская 56/1, действующий на основании Свидетельства о государственной
A9: ='Пр №1'!A8:Q8 -> регистрации индивидуального предпринимателя по Свердловскому району г. Бишкек № 003-2024-169-5930 от 08.08.2024
A10: ИНН: | C10: ='Пр №1'!C9:G9 -> 22212200650516 | H10: именуемый в дальнейшем «Арендодатель», с одной стороны и
A11: ='Акт расч'!A11:H11 -> {{CLIENT_FULLNAME}} | I11: именуемый(-ая) в дальнейшем «Арендатор», действующий(-ая)
A12: =Дог.!A19 -> на основании паспорта: | E12: =Дог.!E19 -> ХХХ | F12: =Дог.!F19 -> № | G12: 2529296 | I12: =Дог.!I19 -> выдан | J12: ='Пр №1'!J11 -> МКК | K12: ='Пр №1'!K11 -> ХХХХ | L12: ='Пр №1'!L11 -> от | M12: ='Пр №1'!M11 -> ХХХХ | N12: =Дог.!N19 -> зарегистрированный(-ая)
A13: по адресу: | C13: ='Акт расч'!C13:G13 -> Чуйская область г. Бишкек | I13: ='Акт расч'!H13:M13 -> ул. ХХХХХ | N13: Факт. место проживания
A14: ='Акт расч'!A14:E14 -> Чуйская область г. Бишкек | H14: ='Пр №1'!H13:Q13 -> ул. ХХХХХ
A15: ПИН: | C15: ='Пр №1'!C14:F14 -> ХХХХ | G15: Адрес объекта: | K15: ='Пр №1'!K14:P14 -> 0
A16: с другой стороны, а вместе именуемые «Стороны», заключили настоящий акт к Договору
A17: аренды оборудования | E17: № | F17: =K5 -> 21 | G17: =L5 -> 11 | H17: =M5 -> 2025 | I17: =N5 -> 45982.791 | J17: =O5 -> 1 | K17: о нижеследующем:
A18: 1. Во исполнение Договора аренды оборудования | J18: № | K18: =K5 -> 21 | L18: =L5 -> 11 | M18: =M5 -> 2025 | N18: =N5 -> 45982.791 | O18: =O5 -> 1
A19: Арендатор возвращает Арендодателю следующее Имущество:
A20: № | B20: Наименование Имущества | G20: Стоимость оборудования | H20: Дата и время выдачи | J20: Дата и время возврата | K20: Кол-во оборуд. | L20: Кол суток | M20: Ед.изм. | N20: Цена в сутки | P20: Сумма сом
A21: 1 | B21: ='Пр №1'!B20 -> {{TOOL_NAME}} | G21: ='Акт прием'!N21 -> 35000 | H21: ='Пр №1'!J20 -> 45982.791 | J21: ='Пр №1'!J20 -> 45982.791 | K21: ='Пр №1'!I20 -> 1 | L21: =J22-H22 -> 0 | M21: Сутки | N21: ='Пр №1'!N20 -> 1500 | P21: =K21*L21*N21 -> 0
H22: ='Акт расч'!F21 -> 45982 | J22: ='Пр №1'!J21 -> 45982
A23: 2 | B23: ='Пр №1'!B22 -> 0 | G23: ='Акт прием'!N23 -> 0 | K23: ='Пр №1'!I22 -> 0 | L23: =J24-H24 -> 0 | N23: ='Пр №1'!N22 -> 0 | P23: =K23*L23*N23 -> 0
A25: 3 | B25: ='Пр №1'!B24 -> 0 | G25: ='Акт прием'!N25 -> 0 | K25: ='Пр №1'!I24 -> 0 | L25: =J26-H26 -> 0 | N25: ='Пр №1'!N24 -> 0 | P25: =K25*L25*N25 -> 0
A27: 4 | B27: ='Пр №1'!B26 -> 0 | G27: ='Акт прием'!N24 -> 0 | K27: ='Пр №1'!I26 -> 0 | L27: =J28-H28 -> 0 | N27: ='Пр №1'!N26 -> 0 | P27: =K27*L27*N27 -> 0
A29: 5 | B29: ='Пр №1'!B28 -> 0 | G29: ='Акт прием'!N25 -> 0 | K29: ='Пр №1'!I28 -> 0 | L29: =J30-H30 -> 0 | N29: ='Пр №1'!N28 -> 0 | P29: =K29*L29*N29 -> 0
M31: ИТОГО: | P31: =SUM(P21:Q30) -> 0
A32: 2. Общая стоимость оказанных услуг составила | H32: =P31 -> 0
A33: 3. Имущество передается в полной исправности. Работоспособность Имущества проверена Арендодателем
A34: 4. Стороны по факту оказанных услуг претензий друг к другу не имеют.
A35: 5. Стороны считают условия Договора аренды оборудования выполненными и претензий друг к другу не имеют
A36: 6. Настоящий Акт составлен в 2-ух экземплярах, имеющих одинаковую юридическую силу, по одному для каждой из сторон.
A39: 8. РЕКВИЗИТЫ СТОРОН
A40: АРЕНДОДАТЕЛЬ: | J40: АРЕНДАТОР:
A41: Ф.И.О.: | B41: ='Пр №1'!B50:G50 -> Зинченко Михаил Александрович | J41: ='Счет '!J47:K47 -> Ф.И.О.: | L41: ='Пр №1'!L50:Q50 -> {{CLIENT_FULLNAME}}
A42: ИНН: | B42: ='Пр №1'!B51:G51 -> 22212200650516 | J42: ='Счет '!J48:K48 -> ПИН: | L42: ='Пр №1'!L51:P51 -> ХХХХ
A43: Паспорт: | C43: ='Пр №1'!C52 -> ID | D43: № | E43: ='Пр №1'!E52:G52 -> 1706490 | J43: ='Счет '!J49:K49 -> Паспорт: | L43: ='Пр №1'!L52 -> ХХХ | M43: № | N43: ='Пр №1'!N52:O52 -> ХХХХХ
A44: Выдан: | C44: ='Пр №1'!C53:G53 -> МКК 211041 от 05.06.2020 | J44: ='Счет '!J50:K50 -> Выдан: | L44: ='Пр №1'!L53 -> МКК | M44: ='Пр №1'!M53 -> ХХХХ | N44: ='Пр №1'!N53 -> от | O44: ='Пр №1'!O53 -> ХХХХ
A45: Адрес: | C45: ='Пр №1'!C54:G54 -> г. Бишкек | J45: ='Счет '!J51:K51 -> Адрес: | L45: ='Пр №1'!L54:Q54 -> Чуйская область г. Бишкек
A46: ='Пр №1'!A55:G55 -> ул. Ялтинская д. № 56 | J46: ='Пр №1'!J55:P55 -> ул. ХХХХХ
A47: Почтовый индекс: | D47: ='Пр №1'!D56:G56 -> 720051 | J47: ='Счет '!J53:L53 -> Почтовый индекс: | M47: ='Пр №1'!M56:N56 -> 0
A48: Банковские реквизиты: | J48: ='Счет '!J54:P54 -> Банковские реквизиты:
...

Sheet Акт слом
A3: АКТ ВОЗВРАТА ИМУЩЕСТВА
A4: к Договору аренды оборудования
J5: № | K5: ='Пр №1'!J3 -> 21 | L5: ='Пр №1'!K3 -> 11 | M5: ='Пр №1'!L3 -> 2025 | N5: ='Пр №1'!M3 -> 45982.791 | O5: ='Акт возв'!O5 -> 1
B6: =Дог.!B13 -> г. Бишкек | I6: ='Пр №1'!I5 -> « | J6: ='Пр №1'!J5 -> 21 | K6: ='Пр №1'!K5 -> » | L6: ='Пр №1'!L5 -> Ноябрь | N6: ='Пр №1'!N5 -> 2025 | O6: ='Пр №1'!O5 -> г.
A7: ='Акт возв'!A7:E7 -> Зинченко Михаил Александрович | G7: ='Акт возв'!G7:Q7 -> 22.12.2006 года рождения, паспорт: ID3219844 выдан MKK 218011от 12.02.2023 г.
A8: ='Пр №1'!A7:Q7 -> зарегистрированный по адресу город Бишкек, улица Ялтинская 56/1, действующий на основании Свидетельства о государственной
A9: ='Пр №1'!A8:Q8 -> регистрации индивидуального предпринимателя по Свердловскому району г. Бишкек № 003-2024-169-5930 от 08.08.2024
A10: ='Акт возв'!A10:G10 -> ИНН: | C10: ='Пр №1'!C9:G9 -> 22212200650516 | H10: именуемый в дальнейшем «Арендодатель», с одной стороны и
A11: =Дог.!A18 -> {{CLIENT_FULLNAME}} | I11: именуемый(-ая) в дальнейшем «Арендатор», действующий(-ая)
A12: =Дог.!A19 -> на основании паспорта: | E12: =Дог.!E19 -> ХХХ | F12: =Дог.!F19 -> № | G12: =Дог.!G19 -> ХХХХХ | I12: =Дог.!I19 -> выдан | J12: =Дог.!J19 -> МКК | K12: ='Пр №1'!K11 -> ХХХХ | L12: ='Пр №1'!L11 -> от | M12: ='Пр №1'!M11 -> ХХХХ | N12: =Дог.!N19 -> зарегистрированный(-ая)
A13: по адресу: | C13: ='Акт возв'!C13:G13 -> Чуйская область г. Бишкек | I13: ='Акт возв'!H13:M13 -> ул. ХХХХХ | N13: Факт. место проживания
A14: ='Акт возв'!A14:E14 -> Чуйская область г. Бишкек | H14: ='Пр №1'!H13:Q13 -> ул. ХХХХХ
A15: ПИН: | C15: ='Пр №1'!C14:F14 -> ХХХХ | G15: Адрес объекта: | K15: ='Пр №1'!K14:P14 -> 0
A16: с другой стороны, а вместе именуемые «Стороны», заключили настоящий акт к Договору
A17: аренды оборудования | E17: № | F17: =K5 -> 21 | G17: =L5 -> 11 | H17: =M5 -> 2025 | I17: =N5 -> 45982.791 | J17: =O5 -> 1 | K17: о нижеследующем:
A18: 1. Во исполнение Договора аренды оборудования | J18: № | K18: =K5 -> 21 | L18: =L5 -> 11 | M18: =M5 -> 2025 | N18: =N5 -> 45982.791 | O18: =O5 -> 1
A19: Арендатор возвращает Арендодателю следующее Имущество:
A20: № | B20: Наименование Имущества | G20: Стоимость оборудования | H20: Дата и время выдачи | J20: Дата и время возврата | K20: Кол-во оборуд. | L20: Кол суток | M20: Ед.изм. | N20: Цена в сутки | P20: Сумма сом
A21: 1 | B21: ='Акт возв'!B21:F22 -> {{TOOL_NAME}} | G21: ='Акт прием'!N21 -> 35000 | H21: ='Пр №1'!J20 -> 45982.791 | J21: ='Пр №1'!J20 -> 45982.791 | K21: ='Акт возв'!K21:K22 -> 1 | L21: =J22-H22 -> 0 | M21: Сутки | N21: ='Пр №1'!N20 -> 1500 | P21: =K21*L21*N21 -> 0
H22: ='Пр №1'!J21 -> 45982 | J22: ='Пр №1'!J21 -> 45982
A23: 2 | B23: ='Акт возв'!B23:F24 -> 0 | G23: ='Акт прием'!N22 -> 0 | K23: ='Акт возв'!K23:K24 -> 0 | N23: ='Пр №1'!N22 -> 0
A25: 3 | B25: ='Акт возв'!B25:F26 -> 0 | G25: ='Акт прием'!N23 -> 0 | K25: ='Акт возв'!K25:K26 -> 0 | N25: ='Пр №1'!N24 -> 0
A27: 4 | B27: ='Акт возв'!B27:F28 -> 0 | G27: ='Акт прием'!N24 -> 0 | K27: ='Акт возв'!K27:K28 -> 0 | N27: ='Пр №1'!N26 -> 0
A29: 5 | B29: ='Акт возв'!B29:F30 -> 0 | G29: ='Акт прием'!N25 -> 0 | K29: ='Акт возв'!K29:K30 -> 0 | N29: ='Пр №1'!N28 -> 0
M31: ИТОГО: | P31: =SUM(P21:Q30) -> 0
A32: 2. Общая стоимость оказанных услуг составила | H32: =P31 -> 0
A33: 2.Следующее имущество возвращается в ненадлежащем состоянии:
A34: № | B34: Наименование Имущества | G34: Реально нанесенный ущерб имуществу | N34: Стоимость ущерба
A35: 1 | B35: =B21 -> {{TOOL_NAME}} | N35: 3500
A36: 2 | B36: =B22 -> 0 | G36: =K22 -> 0
A37: 3 | B37: =B23 -> 0 | G37: =K23 -> 0
A38: 4
A39: 5 | B39: =B24 -> 0 | G39: =K24 -> 0
L40: Итого: | N40: =SUM(N35:Q39) -> 3500
A42: В этой связи согласно пункту 2.2. Договора аренды, за | I42: № | J42: =K18 -> 21 | K42: =L18 -> 11 | L42: =M18 -> 2025 | M42: =N18 -> 45982.791 | N42: =O18 -> 1 | O42: Арендодатель
A43: оценивает размер реально нанесённого ущерба в размере: | J43: =N40 -> 3500
A44: 3. Арендатор обязуется оплатить образовавшуюся задолженность в размере | J44: =J43 -> 3500
A45: 4. Настоящий Акт составлен в 2-ух экземплярах, имеющих одинаковую юридическую силу, по одному для каждой из сторон.
A48: 8. РЕКВИЗИТЫ СТОРОН
A49: АРЕНДОДАТЕЛЬ: | J49: АРЕНДАТОР:
...

Sheet Обяз
A2: =Дог.!B13 -> г. Бишкек | F2: =Дог.!I13 -> « | G2: =Дог.!J13 -> 21 | H2: =Дог.!K13 -> » | I2: =Дог.!L13 -> Ноябрь | K2: =Дог.!N13 -> 2025 | L2: =Дог.!O13 -> г.
A6: ОБЯЗАТЕЛЬСТВО
B9: Я, | C9: =Дог.!A18 -> {{CLIENT_FULLNAME}} | J9: зарегистрированный (-ая)
A10: по адресу | C10: =Дог.!C20 -> Чуйская область г. Бишкек
A11: =Дог.!J20 -> ул. ХХХХХ | G11: Фактическое место проживание
A12: по адресу | C12: =Дог.!A21 -> Чуйская область г. Бишкек
A13: =Дог.!I21 -> ул. ХХХХХ
A14: Паспорт: | C14: =Дог.!E19 -> ХХХ | D14: № | E14: =Дог.!G19 -> ХХХХХ
A15: Выдан: | C15: =Дог.!J19 -> МКК | D15: =Дог.!K19 -> ХХХХ | E15: от | F15: =Дог.!M19 -> ХХХХ
A16: ПИН: | C16: =Дог.!C22 -> ХХХХ
A17: Год рождения | D17: =Дог.!A23 -> ХХХХХ
A18: Телефон | C18: =Дог.!D7 -> {{CLIENT_PHONE}}
A19: даю настоящее обязательство И.П. | F19: =Дог.!A14 -> Зинченко Михаил Александрович
A21: 1. | B21: Обязуюсь погасить задолженность в размере : | J21: 3000
A22: =[2]!ЧислоПрописьюВалюта(J21,2) -> #NAME? | J22: в срок до | K22: ='Пр №1'!J21+3 -> 45985
A23: Задолженность обязуюсь погашать равными долями по | J23: =J21/C24 -> 600
A24: в течении | C24: 5 | D24: месяцев\дней | F24: не позднее | H24: 5 | I24: ,-го рабочего дня каждого месяца
A25: Путем внесения наличных денег в кассу И.П. | G25: =Дог.!A14 -> Зинченко Михаил Александрович
A26: либо на расчетный счет М Банк по номеру | H26: 0 (559) 727 607 | K26: с обязательным
A27: фотографированием чека оплаты задолженности и отправки его на WhatsApp этого же номера.
A28: 2. | B28: Предупрежден что, в случае просрочки выплат по обязательству, будет начисляться неустойка
A29: в соответствии со ст.320 ГК.КР., в размере 1 (один) % от оставшейся суммы общего долга за
A30: каждый день просрочки, от суммы основного долга. В рамках исполнения обязательства в
A31: случае просрочки, в первую очередь погашается неустойка.
A32: 3. | B32: Также предупрежден(а), что в случае неуплаты мною долга, дело о взыскании
A33: задолженности со всеми штрафными начислениями, будет передано в суд по месту нахождения
A34: кредитора г. Бишкек Свердловский районный суд (по адресу ул. Ибраимова д. № 64) в порядке
A35: установленном действующим законодательством КР.( договорная подсудность Ст.34 ГПК К.Р.)
A36: 4. | B36: В случае смены жительства и номеров телефонов обязуюсь в 3-х дневный срок
A37: сообщить новые данные.
A40: (Ф.И.О., должника) | J40: (подпись должника)
A43: (Ф.И.О., поручителя) | J43: (подпись поручителя)
A46: (Ф.И.О., поручителя) | J46: (подпись поручителя)
A48: Зинченко Михаил Александрович
A49: (Ф.И.О., кредитора) | J49: (подпись кредитора)

Sheet Счет 
A4: СЧЕТ НА ОПЛАТУ
J5: № | K5: ='Пр №1'!J3 -> 21 | L5: ='Пр №1'!K3 -> 11 | M5: ='Пр №1'!L3 -> 2025 | N5: ='Пр №1'!M3 -> 45982.791 | O5: ='Акт слом'!O5 -> 1
B6: =Дог.!B13 -> г. Бишкек | I6: ='Пр №1'!I5 -> « | J6: ='Пр №1'!J5 -> 21 | K6: ='Пр №1'!K5 -> » | L6: ='Пр №1'!L5 -> Ноябрь | N6: ='Пр №1'!N5 -> 2025 | O6: ='Пр №1'!O5 -> г.
A7: ='Акт расч'!A7:E7 -> Зинченко Михаил Александрович | G7: ='Акт расч'!G7:Q7 -> 22.12.2006 года рождения, паспорт: ID3219844 выдан MKK 218011от 12.02.2023 г.
A8: ='Пр №1'!A7:Q7 -> зарегистрированный по адресу город Бишкек, улица Ялтинская 56/1, действующий на основании Свидетельства о государственной
A9: ='Пр №1'!A8:Q8 -> регистрации индивидуального предпринимателя по Свердловскому району г. Бишкек № 003-2024-169-5930 от 08.08.2024
A10: ИНН: | B10: ='Пр №1'!C9 -> 22212200650516 | E10: =A54 -> Банковские реквизиты: | H10: =A55 -> ОАО Комерческий банк Кыргызстан | P10: =A57 -> БИК: | Q10: =B57 -> 103001
A11: =A56 -> р/c: | B11: =B56 -> "1030120300369929" | G11: =A58 -> УГНС 003 Свердловского района
A13: 1. Во исполнение Договора аренды оборудования | J13: № | K13: =K5 -> 21 | L13: =L5 -> 11 | M13: =M5 -> 2025 | N13: =N5 -> 45982.791 | O13: =O5 -> 1
A14: Арендатор оплачивает арендную плату Арендодателю за пользование оборудованием:
A15: Арендатор: | C15: ='Акт расч'!A11 -> {{CLIENT_FULLNAME}}
A16: № | B16: Наименование оборудования | H16: Кол. Оборудования | J16: Кол. Суток | L16: Ед.изм. | N16: Цена в сутки | P16: Сумма сом
A17: 1 | B17: ='Акт расч'!B20 -> {{TOOL_NAME}} | H17: ='Акт расч'!J20 -> 1 | J17: ='Акт расч'!L20 -> 0 | L17: ='Акт расч'!M20 -> Сут | N17: ='Акт расч'!N20 -> 1500 | P17: ='Акт расч'!P20 -> 0
A18: 2 | B18: ='Акт расч'!B22 -> 0 | H18: ='Акт расч'!J22 -> 0 | J18: ='Акт расч'!L22 -> 0 | L18: ='Акт расч'!M22 -> 0 | N18: ='Акт расч'!N22 -> 0 | P18: ='Акт расч'!P22 -> 0
A19: 3 | B19: ='Акт расч'!B24 -> 0 | H19: ='Акт расч'!J24 -> 0 | J19: ='Акт расч'!L24 -> 0 | L19: ='Акт расч'!M24 -> 0 | N19: ='Акт расч'!N24 -> 0 | P19: ='Акт расч'!P24 -> 0
A20: 4 | B20: ='Акт расч'!B26 -> 0 | H20: ='Акт расч'!J26 -> 0 | J20: ='Акт расч'!L26 -> 0 | L20: ='Акт расч'!M26 -> 0 | N20: ='Акт расч'!N26 -> 0 | P20: ='Акт расч'!P26 -> 0
A21: 5 | B21: ='Акт расч'!B28 -> 0 | H21: ='Акт расч'!J28 -> 0 | J21: ='Акт расч'!L28 -> 0 | L21: ='Акт расч'!M28 -> 0 | N21: ='Акт расч'!N28 -> 0 | P21: ='Акт расч'!P28 -> 0
A22: 6 | B22: ='Акт расч'!B30 -> 0 | H22: ='Акт расч'!J30 -> 0 | J22: ='Акт расч'!L30 -> 0 | L22: ='Акт расч'!M30 -> 0 | N22: ='Акт расч'!N30 -> 0 | P22: ='Акт расч'!P30 -> 0
A23: 7 | B23: ='Акт расч'!B32 -> 0 | H23: ='Акт расч'!J32 -> 0 | J23: ='Акт расч'!L32 -> 0 | L23: ='Акт расч'!M32 -> 0 | N23: ='Акт расч'!N32 -> 0 | P23: ='Акт расч'!P32 -> 0
A24: 8 | B24: ='Акт расч'!B34 -> 0 | H24: ='Акт расч'!J34 -> 0 | J24: ='Акт расч'!L34 -> 0 | L24: ='Акт расч'!M34 -> 0 | N24: ='Акт расч'!N34 -> 0 | P24: ='Акт расч'!P34 -> 0
A25: 9 | B25: ='Акт расч'!B36 -> 0 | H25: ='Акт расч'!J36 -> 0 | J25: ='Акт расч'!L36 -> 0 | L25: ='Акт расч'!M36 -> 0 | N25: ='Акт расч'!N36 -> 0 | P25: ='Акт расч'!P36 -> 0
A26: 10 | B26: ='Акт расч'!B38 -> 0 | H26: ='Акт расч'!J38 -> 0 | J26: ='Акт расч'!L38 -> 0 | L26: ='Акт расч'!M38 -> 0 | N26: ='Акт расч'!N38 -> 0 | P26: ='Акт расч'!P38 -> 0
A27: 11
A28: 12
A29: 13
A30: 14
A31: 15
A32: 16 | N32: Всего: | P32: =SUM(P17:Q31) -> 0
A33: 17
A34: 18
A35: 19
A36: 20
A37: 21
A38: 22
A39: 23 | B39: Итого к оплате: | P39: =P32 -> 0
A41: К оплате: | C41: =[2]!ЧислоПрописьюВалюта(P39,2) -> #NAME?
A45: 8. РЕКВИЗИТЫ СТОРОН
A46: АРЕНДОДАТЕЛЬ: | J46: АРЕНДАТОР:
A47: Ф.И.О.: | B47: ='Пр №1'!B50:G50 -> Зинченко Михаил Александрович | J47: ='Акт расч'!J59:K59 -> Ф.И.О.: | L47: ='Пр №1'!L50:Q50 -> {{CLIENT_FULLNAME}}
A48: ИНН: | B48: ='Пр №1'!B51:G51 -> 22212200650516 | J48: ='Акт расч'!J60:K60 -> ПИН: | L48: ='Пр №1'!L51:P51 -> ХХХХ
...

Sheet Фактура
A4: СЧЕТ ФАКТУРА
J5: № | K5: ='Пр №1'!J3 -> 21 | L5: ='Пр №1'!K3 -> 11 | M5: ='Пр №1'!L3 -> 2025 | N5: ='Пр №1'!M3 -> 45982.791 | O5: 1
B6: =Дог.!B13 -> г. Бишкек | I6: ='Пр №1'!I5 -> « | J6: ='Пр №1'!J5 -> 21 | K6: ='Пр №1'!K5 -> » | L6: ='Пр №1'!L5 -> Ноябрь | N6: ='Пр №1'!N5 -> 2025 | O6: ='Пр №1'!O5 -> г.
A7: ='Акт расч'!A7:E7 -> Зинченко Михаил Александрович | G7: ='Акт расч'!G7:Q7 -> 22.12.2006 года рождения, паспорт: ID3219844 выдан MKK 218011от 12.02.2023 г.
A8: ='Пр №1'!A7:Q7 -> зарегистрированный по адресу город Бишкек, улица Ялтинская 56/1, действующий на основании Свидетельства о государственной
A9: ='Пр №1'!A8:Q8 -> регистрации индивидуального предпринимателя по Свердловскому району г. Бишкек № 003-2024-169-5930 от 08.08.2024
A10: ИНН: | B10: ='Пр №1'!C9 -> 22212200650516 | F10: =A54 -> Банковские реквизиты: | I10: =A55 -> ОАО Комерческий банк Кыргызстан
A11: =A56 -> р/c: | B11: =B56 -> "1030120300369929" | G11: =A58 -> УГНС 003 Свердловского района | L11: ='Пр №1'!A60 -> БИК: | N11: ='Пр №1'!B60 -> 103001
A13: 1. Во исполнение Договора аренды оборудования | J13: № | K13: =K5 -> 21 | L13: =L5 -> 11 | M13: =M5 -> 2025 | N13: =N5 -> 45982.791 | O13: 1
A14: Арендатор оплатил арендную плату Арендодателю за пользование оборудованием:
A15: Арендатор: | C15: ='Акт расч'!A11 -> {{CLIENT_FULLNAME}}
A16: № | B16: Наименование оборудования | H16: Кол. Оборудования | J16: Кол. Суток | L16: Ед.изм. | N16: Цена в сутки | P16: Сумма сом
A17: 1 | B17: ='Счет '!B17 -> {{TOOL_NAME}} | H17: ='Счет '!H17:I17 -> 1 | J17: ='Счет '!J17:K17 -> 0 | L17: ='Счет '!L17:M17 -> Сут | N17: ='Счет '!N17:O17 -> 1500 | P17: ='Счет '!P17:Q17 -> 0
A18: 2 | B18: ='Счет '!B18 -> 0 | H18: ='Счет '!H18:I18 -> 0 | J18: ='Счет '!J18:K18 -> 0 | L18: ='Счет '!L18:M18 -> 0 | N18: ='Счет '!N18:O18 -> 0 | P18: ='Счет '!P18:Q18 -> 0
A19: 3 | B19: ='Счет '!B19 -> 0 | H19: ='Счет '!H19:I19 -> 0 | J19: ='Счет '!J19:K19 -> 0 | L19: ='Счет '!L19:M19 -> 0 | N19: ='Счет '!N19:O19 -> 0 | P19: ='Счет '!P19:Q19 -> 0
A20: 4 | B20: ='Счет '!B20 -> 0 | H20: ='Счет '!H20:I20 -> 0 | J20: ='Счет '!J20:K20 -> 0 | L20: ='Счет '!L20:M20 -> 0 | N20: ='Счет '!N20:O20 -> 0 | P20: ='Счет '!P20:Q20 -> 0
A21: 5 | B21: ='Счет '!B21 -> 0 | H21: ='Счет '!H21:I21 -> 0 | J21: ='Счет '!J21:K21 -> 0 | L21: ='Счет '!L21:M21 -> 0 | N21: ='Счет '!N21:O21 -> 0 | P21: ='Счет '!P21:Q21 -> 0
A22: 6 | B22: ='Счет '!B22 -> 0 | H22: ='Счет '!H22:I22 -> 0 | J22: ='Счет '!J22:K22 -> 0 | L22: ='Счет '!L22:M22 -> 0 | N22: ='Счет '!N22:O22 -> 0 | P22: ='Счет '!P22:Q22 -> 0
A23: 7 | B23: ='Счет '!B23 -> 0 | H23: ='Счет '!H23:I23 -> 0 | J23: ='Счет '!J23:K23 -> 0 | L23: ='Счет '!L23:M23 -> 0 | N23: ='Счет '!N23:O23 -> 0 | P23: ='Счет '!P23:Q23 -> 0
A24: 8 | B24: ='Счет '!B24 -> 0 | H24: ='Счет '!H24:I24 -> 0 | J24: ='Счет '!J24:K24 -> 0 | L24: ='Счет '!L24:M24 -> 0 | N24: ='Счет '!N24:O24 -> 0 | P24: ='Счет '!P24:Q24 -> 0
A25: 9 | B25: ='Счет '!B25 -> 0 | H25: ='Счет '!H25:I25 -> 0 | J25: ='Счет '!J25:K25 -> 0 | L25: ='Счет '!L25:M25 -> 0 | N25: ='Счет '!N25:O25 -> 0 | P25: ='Счет '!P25:Q25 -> 0
A26: 10 | B26: ='Счет '!B26 -> 0 | H26: ='Счет '!H26:I26 -> 0 | J26: ='Счет '!J26:K26 -> 0 | L26: ='Счет '!L26:M26 -> 0 | N26: ='Счет '!N26:O26 -> 0 | P26: ='Счет '!P26:Q26 -> 0
A27: 11 | B27: ='Счет '!B27 -> 0 | H27: ='Счет '!H27:I27 -> 0 | J27: ='Счет '!J27:K27 -> 0 | L27: ='Счет '!L27:M27 -> 0 | N27: ='Счет '!N27:O27 -> 0 | P27: ='Счет '!P27:Q27 -> 0
A28: 12 | B28: ='Счет '!B28 -> 0 | H28: ='Счет '!H28:I28 -> 0 | J28: ='Счет '!J28:K28 -> 0 | L28: ='Счет '!L28:M28 -> 0 | N28: ='Счет '!N28:O28 -> 0 | P28: ='Счет '!P28:Q28 -> 0
... A31: 15 | B31: ='Счет '!B31 -> 0 | H31: ='Счет '!H31:I31 -> 0 | J31: ='Счет '!J31:K31 -> 0 | L31: ='Счет '!L31:M31 -> 0 | N31: ='Счет '!N31:O31 -> 0 | P31: ='Счет '!P31:Q31 -> 0
A32: 16 | N32: Всего: | P32: =SUM(P17:Q31) -> 0
A33: 17
A34: 18
A35: 19
A36: 20
A37: 21
A38: 22
A39: 23 | B39: Итого к оплате: | P39: =P32 -> 0
A41: К оплате: | C41: =[2]!ЧислоПрописьюВалюта(P39,2) -> #NAME?
A45: 8. РЕКВИЗИТЫ СТОРОН
A46: АРЕНДОДАТЕЛЬ: | J46: АРЕНДАТОР:
A47: Ф.И.О.: | B47: ='Пр №1'!B50:G50 -> Зинченко Михаил Александрович | J47: ='Акт расч'!J59:K59 -> Ф.И.О.: | L47: ='Пр №1'!L50:Q50 -> {{CLIENT_FULLNAME}}
A48: ИНН: | B48: ='Пр №1'!B51:G51 -> 22212200650516 | J48: ='Акт расч'!J60:K60 -> ПИН: | L48: ='Пр №1'!L51:P51 -> ХХХХ
A49: Паспорт: | C49: ='Пр №1'!C52 -> ID | D49: № | E49: ='Пр №1'!E52:G52 -> 1706490 | J49: ='Акт расч'!J61:K61 -> Паспорт: | L49: ='Пр №1'!L52 -> ХХХ | M49: № | N49: ='Пр №1'!N52:O52 -> ХХХХХ
A50: Выдан: | C50: ='Пр №1'!C53:G53 -> МКК 211041 от 05.06.2020 | J50: ='Акт расч'!J62:K62 -> Выдан: | L50: ='Пр №1'!L53 -> МКК | M50: ='Пр №1'!M53 -> ХХХХ | O50: ='Пр №1'!N53 -> от | P50: ='Пр №1'!O53 -> ХХХХ
...

Sheet ПКО
AP1: Унифицированная форма № КО-1 | BP1: =A8 -> Зинченко Михаил Александрович
W2: =РКО!AV2 -> Утверждена постановлением нацкомитета Кыргызской республики от 07.04.2003 №4 | BP2: =A9 -> организация
BP3: Народная аренда строительного инструмента
BP4: структурное подразделение
AZ6: Код | BP6: КВИТАНЦИЯ
AX7: Форма по ГКУД | AZ7: 0310002
A8: =Дог.!A14 -> Зинченко Михаил Александрович | AX8: по ОКПО | AZ8: 32282661
A9: организация
A10: Народная аренда строительного инструмента | BN10: к приходному кассовому ордеру № | CG10: =AJ15 -> 21 | CJ10: =AN15 -> 11 | CL10: =AQ15 -> 2025 | CP10: =AU15 -> 45982.791 | CT10: =AZ15 -> 1
A11: структурное подразделение
BP12: от « | BS12: ='Акт слом'!J6 -> 21 | BU12: » | BV12: ='Акт слом'!L6 -> Ноябрь | CG12: ='Акт слом'!N6 -> 2025 | CK12: г.
AJ13: Номер документа | BB13: Дата
A14: ПРИХОДНЫЙ КАССОВЫЙ ОРДЕР | BB14: составления | BP14: Принято от | BX14: =TRIM(SUBSTITUTE(LEFT(I23&" ",SEARCH(" ",I23&" ")+1)&"."& MID(I23&" ",SEARCH(" ",I23&" ",SEARCH(" ",I23&" ")+1),2)&"."," .",)) -> #VALUE!
AJ15: =Фактура!K5 -> 21 | AN15: =Фактура!L5 -> 11 | AQ15: =Фактура!M5 -> 2025 | AU15: =Фактура!N5 -> 45982.791 | AZ15: =Фактура!O5 -> 1 | BB15: ='Пр №1'!J21 -> 45982
BP16: Основание: | BW16: =I25 -> Обеспечительный платеж
A17: Дебет | G17: Кредит | AM17: Сумма, | AW17: Код | BP17: =AI25 -> Аренда строительного оборудования
L18: код | U18: корреспон- | AD18: код | AM18: сом. тыйын. | AW18: целевого | BP18: =A26 -> {{TOOL_NAME}}
L19: структурного | U19: дирующий | AD19: аналитичес- | AM19: =BU21 -> 3000 | AW19: назначения
L20: подразделения | U20: счет, субсчет | AD20: кого учета
L21: 1 | U21: 1234587 | AD21: 6598 | AM21: ='Акт расч'!P42 -> 0 | AW21: 200 | BP21: Сумма | BU21: ='Пр №1'!P30 -> 3000 | CM21: 00 | CO21: тыйын
BU22: цифрами
A23: Принято от | I23: =Дог.!A18 -> {{CLIENT_FULLNAME}} | BN23: =[2]!ЧислоПрописьюВалюта(BU21,2) -> #NAME?
A25: Основание: | I25: Обеспечительный платеж | AI25: Аренда строительного оборудования
A26: ='Пр №1'!B20 -> {{TOOL_NAME}} | BN26: прописью
A27: Сумма | F27: =BN23 -> #NAME? | BP27: В том числе
F28: прописью
BP29: « | BQ29: =BS12 -> 21 | BS29: » | BT29: =BV12 -> Ноябрь | CE29: =CG12 -> 2025 | CI29: г.
A30: В том числе
A31: Приложение | BN31: М. П. (штампа)
A33: Главный бухгалтер | Z33: =Дог.!A67 -> Зинченко М. А. | BN33: Главный бухгалтер | CK33: =Z33 -> Зинченко М. А.
N34: (подпись) | Z34: (расшифровка подписи) | CB34: (подпись) | CK34: (расшифровка подписи)
A36: Получил кассир | Z36: Купрей А. А. | BP36: Кассир | CG36: =Z36 -> Купрей А. А.
N37: (подпись) | Z37: (расшифровка подписи) | BU37: (подпись) | CG37: (расшифровка подписи)

Sheet РКО
BM1: Унифицированная форма № КО-2
AV2: Утверждена постановлением нацкомитета Кыргызской республики от 07.04.2003 №4
CT4: Код
CQ5: Форма по ОКУД | CT5: 0310002
A6: =ПКО!A8 -> Зинченко Михаил Александрович | CQ6: по ОКПО | CT6: =ПКО!AZ8 -> 32282661
A7: (организация)
A8: =ПКО!A10 -> Народная аренда строительного инструмента
A9: (структурное подразделение)
CC10: Номер документа | CT10: Дата составления
BR11: РАСХОДНЫЙ КАССОВЫЙ ОРДЕР | BU11: =ПКО!AJ15 -> 21 | BZ11: =ПКО!AN15 -> 11 | CD11: =ПКО!AQ15 -> 2025 | CJ11: =ПКО!AU15 -> 45982.791 | CQ11: =ПКО!AZ15 -> 1 | CT11: =ПКО!BB15 -> 45982
A13: Дебет | BT13: Кредит | CC13: Сумма, сом тыйын | CQ13: Код целевого назначения
H14: код структурного подразделения | AA14: корреспондирующий счет, субсчет | AV14: код аналитического учета
H15: =ПКО!L21 -> 1 | AA15: =ПКО!U21 -> 1234587 | AV15: =ПКО!AD21 -> 6598 | CC15: =ПКО!BU21 -> 3000 | CQ15: =ПКО!AW21 -> 200
A17: Выдать | H17: =ПКО!I23 -> {{CLIENT_FULLNAME}}
H18: (фамилия, имя, отчество)
A19: Основание: | K19: Возврат | R19: =ПКО!BW16 -> Обеспечительный платеж | AO19: =ПКО!BP17 -> Аренда строительного оборудования | BY19: =ПКО!BP18 -> {{TOOL_NAME}}
A20: Сумма | G20: =ПКО!BN23 -> #NAME?
G21: (прописью)
A22: Приложение
A23: Руководитель организации | Z23: Предприниматель | BR23: ='Пр №1'!A63 -> Зинченко М. А.
Z24: (должность) | AZ24: (подпись) | BR24: (расшифровка подписи)
A25: Главный бухгалтер | AK25: =ПКО!CG36 -> Купрей А. А.
S26: (подпись) | AK26: (расшифровка подписи)
A27: Получил | I27: =G20 -> #NAME?
I28: (сумма прописью)
A29: " | C29: =BU11 -> 21 | G29: " | J29: =Дог.!L13 -> Ноябрь | AC29: =CD11 -> 2025 | AJ29: г. | BA29: Подпись
A30: По | D30: паспорту | R30: =Дог.!E19 -> ХХХ | V30: =Дог.!F19 -> № | Z30: =Дог.!G19 -> ХХХХХ | AJ30: =Дог.!I19 -> выдан | AS30: =Дог.!J19 -> МКК | AY30: =Дог.!K19 -> ХХХХ | BG30: =Дог.!L19 -> от | BL30: =Дог.!M19 -> ХХХХ | BU30: =Дог.!N19 -> зарегистрированный(-ая) | CP30: =Дог.!A20 -> по адресу:
D31: (наименование, номер, дата и место выдачи документа, удостоверяющего личность получателя)
A32: =Дог.!C20 -> Чуйская область г. Бишкек | BG32: =Дог.!J20 -> ул. ХХХХХ
A34: Выдал кассир
O35: (подпись) | AG35: (расшифровка подписи)

Sheet Пасп Доп Данные
A39: Акт дополнительных данных
K40: =Дог.!G8 -> Филиал № | M40: =Дог.!L8 -> ул. Лермонтова д.№ 68
M42: Дата: | N42: ='Пр №1'!J21 -> 45982
B43: г. Бишкек
A44: Арендодатель: | K44: Арендатор:
A45: ='Пр №1'!B50 -> Зинченко Михаил Александрович | K45: ='Пр №1'!L50 -> {{CLIENT_FULLNAME}}
A46: № | B46: Должник | C46: Паспортные данные | E46: Телефон | F46: Адрес | I46: Инструмент | J46: Кол-во суток | K46: Задолженность | L46: Примечание
A47: 1 | B47: ='Пр №1'!A10 -> {{CLIENT_FULLNAME}} | C47: =Дог.!E19 -> ХХХ | D47: =Дог.!G19 -> ХХХХХ | E47: =Дог.!D7 -> {{CLIENT_PHONE}} | F47: Рег. по паспорту | G47: =Дог.!C20 -> Чуйская область г. Бишкек | H47: =Дог.!J20 -> ул. ХХХХХ | I47: ='Пр №1'!B20 -> {{TOOL_NAME}} | J47: ='Акт расч'!L20 -> 0 | K47: ='Акт расч'!P48 -> -3000
C48: =Дог.!J19 -> МКК | F48: Факт. место жительство | G48: =Дог.!A21 -> Чуйская область г. Бишкек | H48: =Дог.!I21 -> ул. ХХХХХ
C49: =Дог.!A22 -> ПИН: | D49: =Дог.!C22 -> ХХХХ
A50: № | B50: Родственники, друзья, знакомые. | C50: Паспортные данные | E50: Телефон | F50: Адрес | L50: Примечание
A51: 1 | B51: Жена
C53: =C49 -> ПИН:
A54: 2 | B54: Мать
C56: =C53 -> ПИН:
A57: 3 | B57: Любовница
C59: =C56 -> ПИН:
A60: 4
C62: =C59 -> ПИН:

Sheet Треб1
M1: 1
J2: И.П. | L2: =G40 -> Зинченко М. А.
J3: Контактный телефон
J4: =Дог.!M7 -> =D7
J5: E-mail: alex.zin4@yandex.ru | O5: Взяли оборудование не оплатили арендную платы и не вернули оборудование
A9: УВЕДОМЛЕНИЕ АРЕНДАТОРУ
D11: Уважаемый (-ая) | F11: =Дог.!$A$18 -> {{CLIENT_FULLNAME}} | L11: =Дог.!A23 -> ХХХХХ | M11: г.р.
A13: Согласно договору аренды оборудования за № | G13: =Дог.!J10 -> 21 | H13: =Дог.!K10 -> 11 | I13: =Дог.!L10 -> 2025 | J13: =Дог.!M10 -> 45982.791 | K13: от | L13: ='Пр №1'!J21 -> 45982
A14: Вы взяли во временное пользование Имущество и обязались оплатить арендную плату за пользование и возвратить
A15: оборудование в порядке и сроки указанные в Приложении №1 настоящего договора аренды оборудования.
A16: Установленный договором срок возврата Имущества и оплаты арендной оплаты истек: | J16: ='Пр №1'!K31 -> 45982.791 | L16: ='Пр №1'!M31 -> 45983
A17: Вы не возвратили арендованное имущество в оговоренный срок и не оплатили стоимость арендной платы за пользование
A18: Имуществом.
A19: =H2 -> 0 | C19: уведомляет что на | F19: ='Пр №1'!J21 -> 45982 | G19: у Вас имеется задолженность по арендной плате за пользование
A20: Имуществом в размере: | D20: ='Акт расч'!P48 -> -3000
A22: Прошу Вас до | C22: =F19+1 -> 45983 | E22: произвести оплату вашей задолженности и вернуть оборудование.
A24: А также напоминаю Вам, что заключённый между нами договор имущественного найма содержит следующие пункты:
A25: 2.5. Если Арендатор не возвратил арендованное имущество либо возвратил его несвоевременно, то Арендатор оплачивает
A26: арендную плату Арендодателю за пользование имуществом за все время просрочки (за все время нахождения имущества
A27: у Арендатора) в соответствии со ч 2. ст.561 ГК.К.Р. пункт 2
A28: 2.8. В случае невозвращения нанятого имущества в установленный договором срок, Арендатор оплачивает неустойку,
A29: в размере 1 (один) % от стоимости оборудования, за каждые сутки просрочки (стоимость оборудования указана в акте
A30: приема передачи) в соответствии со ч 2. ст.561 ГК.К.Р. пункт 2.
A31: 2.7. В случае задержки имущества более оговоренного срока, известить об этом Арендодателя за 1-и сутки и лично явится
A32: в пункт проката для продления договора аренды на новый срок.
A35: Ввиду вышеизложенного Вам необходимо произвести оплату образовавшейся задолженности и вернуть оборудование.
B40: Дата: | C40: =F19 -> 45982 | G40: =Дог.!A67 -> Зинченко М. А.
J41: (Подпись)
M45: 2
J46: И.П. | L46: =G40 -> Зинченко М. А.
J47: Контактный телефон
J48: =J4 -> =D7
J49: E-mail: alex.zin4@yandex.ru | O49: =O5 -> Взяли оборудование не оплатили арендную платы и не вернули оборудование
A53: ПРЕТЕНЗИЯ О ЗАДОЛЖНОСТИ
D55: Уважаемый (-ая) | F55: =Дог.!$A$18 -> {{CLIENT_FULLNAME}} | L55: =L11 -> ХХХХХ | M55: г.р.
A57: Согласно договору аренды оборудования за № | G57: =G13 -> 21 | H57: =H13 -> 11 | I57: =I13 -> 2025 | J57: =J13 -> 45982.791 | K57: от | L57: =L13 -> 45982
A58: Вы взяли во временное пользование Имущество и обязались оплатить арендную плату за пользование и возвратить
A59: оборудование в порядке и сроки указанные в Приложении №1 настоящего договора аренды оборудования.
A60: Установленный договором срок возврата Имущества и оплаты арендной оплаты истек: | J60: =J16 -> 45982.791 | L60: =L16 -> 45983
A61: Вы не возвратили арендованное имущество в оговоренный срок и не оплатили стоимость арендной платы за пользование
...

Sheet Треб2
M1: 1
H2: И.П. Зинченко М. А.
J3: Контактный телефон
J4: =Дог.!M7 -> =D7
J5: E-mail: alex.zin4@yandex.ru | O5: Оборудование вернули но не оплатили
A9: УВЕДОМЛЕНИЕ АРЕНДАТОРУ
D11: Уважаемый (-ая) | F11: =Дог.!$A$18 -> {{CLIENT_FULLNAME}} | L11: =Дог.!A23 -> ХХХХХ | M11: г.р.
A13: Согласно договору аренды оборудования за № | G13: =Дог.!J10 -> 21 | H13: =Дог.!K10 -> 11 | I13: =Дог.!L10 -> 2025 | J13: =Дог.!M10 -> 45982.791 | K13: от | L13: ='Пр №1'!J21 -> 45982
A14: Вы взяли во временное пользование Имущество и обязались оплатить арендную плату за пользование Имуществом в сроки
A15: указанные в АКТЕ РАССЧЕТА АРЕНДНОЙ ПЛАТЫ. Вы обязались оплатить задолженность не позднее 5 рабочих дней с момента
A16: подписания акта. Также вы подписали ОБЯЗАТЕЛЬСТВО по которому вы обязались погасить задолженность в срок до
A17: =Обяз!K22 -> 45985
A18: Вы не оплатили стоимость арендной платы в оговоренный срок за пользование Имуществом.
A20: =H2 -> И.П. Зинченко М. А. | C20: уведомляет что на | F20: ='Пр №1'!J21 -> 45982 | G20: у Вас имеется задолженность по арендной плате за пользование
A21: Имуществом в размере: | D21: ='Акт расч'!P48 -> -3000
A23: Прошу Вас до | C23: =F20+1 -> 45983 | E23: произвести оплату вашей задолженности.
A25: А также напоминаю Вам, что заключённый между нами договор имущественного найма содержит следующие пункты:
A26: 3.4. Арендатор (наниматель) обязан своевременно вносить плату за пользованием имуществом. (в соответствии со ст. 551 ГК.К.Р.)
A27: 3.5. При возврате Имущества, Арендатор обязан оплатить арендную плату за пользование Имуществом, не позднее 5 (пяти)
A28: рабочих дней с момента возврата Имущества Арендодателю.
A29: 3.6. В случае просрочки арендного платежа в установленный договором срок (5 (пять) рабочих дней), Арендатор оплачивает
A30: неустойку, в размере 1 (один) % от стоимости оборудования, за каждые сутки просрочки (стоимость оборудования указана
A31: в акте приема передачи)
A32: При подписании ОБЯЗАТЕЛЬСТВА Вас уведомили о том что, в случае просрочки выплат по обязательству, будет начисляться
A33: неустойка в соответствии со ст.320 ГК.КР., в размере 1 (один) % от оставшейся суммы общего долга за каждый день просрочки, от
A34: суммы основного долга. В рамках исполнения обязательства в случае просрочки, в первую очередь погашается неустойка.
A35: Также предупреждены, что в случае неуплаты Вами долга, дело о взыскании задолженности со всеми штрафными начислениями,
A36: будет передано в суд по месту нахождения кредитора г. Бишкек Свердловский районный суд (по адресу ул. Ибраимова д. № 64)
... A40: Ввиду вышеизложенного Вам необходимо произвести оплату образовавшейся задолженности.
B45: Дата: | C45: =F20 -> 45982 | G45: Зинченко М.А.
J46: (Подпись)
M50: 2
H51: =H2 -> И.П. Зинченко М. А.
J52: Контактный телефон
J53: =J4 -> =D7
J54: E-mail: alex.zin4@yandex.ru | O54: =O5 -> Оборудование вернули но не оплатили
A58: ПРЕТЕНЗИЯ О ЗАДОЛЖЕННОСТИ
D60: Уважаемый (-ая) | F60: =Дог.!$A$18 -> {{CLIENT_FULLNAME}} | L60: =L11 -> ХХХХХ | M60: г.р.
A62: Согласно договору аренды оборудования за № | G62: =G13 -> 21 | H62: =H13 -> 11 | I62: =I13 -> 2025 | J62: =J13 -> 45982.791 | K62: от | L62: =L13 -> 45982
A63: Вы взяли во временное пользование Имущество и обязались оплатить арендную плату за пользование Имуществом в сроки
...

Sheet Обоснование
A1: 1 | B1: ФИО: | C1: =Дог.!A18 -> {{CLIENT_FULLNAME}}
A2: 2 | B2: ТЕКСТ: | C2: Здравствуйте!!! Опубликуйте пожалуйста!!! МОШЕННИК!!!
A3: 3 | B3: Год Рождения: | C3: =Дог.!A23 -> ХХХХХ
A4: 4 | B4: Телефон: | C4: =Дог.!D7 -> {{CLIENT_PHONE}}
A5: 5 | B5: WhatsApp:
A6: 6 | B6: Адрес по прописке: | C6: =Дог.!C20 -> Чуйская область г. Бишкек | D6: =Дог.!J20 -> ул. ХХХХХ
A7: 7 | B7: Адрес проживания: | C7: =Дог.!A21 -> Чуйская область г. Бишкек | D7: =Дог.!I21 -> ул. ХХХХХ
A8: 8 | B8: Что взял: | C8: =Дог.!A12 -> {{TOOL_NAME}}
A9: 9 | B9: Когда взял: | C9: ='Акт расч'!F21 -> 45982
A10: 10 | B10: Вернул\не вернул:
A11: 11 | B11: Задолженность на дату: | C11: ='Пр №1'!J21 -> 45982 | D11: ='Акт расч'!P48 -> -3000
A12: 12 | B12: Что обещал, когда обещал:
A14: 13 | B14: Дополнительные сведения:
A16: 14 | B16: Обязательство - есть\нет:
A17: 15 | B17: Профиль INSTAGRAM:
A18: 16 | B18: Профиль FACEBOOK:
A19: 17 | B19: Профиль Одноклассники:
A20: 18 | B20: Профиль VK:
A21: 19 | B21: Пункт Проката: | C21: =Дог.!L8 -> ул. Лермонтова д.№ 68
A23: Для публикациив соц. сетях хештеги
A24: # | B24: =SUBSTITUTE(C1,CHAR(32),"") -> {{CLIENT_FULLNAME}} | E24: =C1 -> {{CLIENT_FULLNAME}}
A25: # | B25: =SUBSTITUTE(E25,CHAR(32),"") -> #VALUE! | E25: =LEFT(E24,FIND(" ",E24,1)+1)&"."&MID(E24,FIND(" ",E24,FIND(" ",E24,1)+1)+1,1)&"." -> #VALUE!
A26: # | B26: =SUBSTITUTE(E26,CHAR(32),"") -> #VALUE! | E26: =LEFT(E24,SEARCH(" ",E24,SEARCH(" ",E24)+1)-1) -> #VALUE!
A27: # | B27: =SUBSTITUTE(E27,CHAR(32),"") -> #VALUE! | E27: =MID(E26,SEARCH(" ",E26)+1,300)&" "&MID(E26,1,SEARCH(" ",E26)) -> #VALUE!
A28: # | B28: =SUBSTITUTE(E28,CHAR(32),"") -> #VALUE! | E28: =TRIM(RIGHT(E24,LEN(E24)-SEARCH(" ",E24))&" "&LEFT(E24,SEARCH(" ",E24)-1)) -> #VALUE!
A29: # | B29: =SUBSTITUTE(E29,CHAR(32),"") -> #VALUE! | E29: =MID(C1,SEARCH(" ",C1)+1,99) -> #VALUE!
A30: #
A31: #

Sheet Письма
A1: ПИСЬМО ДЛЯ РОДСТВЕННИКОВ И ДРУЗЕЙ № 1
A3: Добрый день, хотел у вас узнать знаете ли вы гражданина Кыргызской Республики
A4: =Дог.!A18 -> {{CLIENT_FULLNAME}} | F4: =Дог.!A23 -> ХХХХХ | H4: данный гражданин
A5: взял и не вернул строительное оборудование на сумму: | H5: ='Акт прием'!N26 -> 35000
A6: я ищу его родственников или знакомых, может что с ним случилось, может попал
A7: в аварию, телефон недоступен по WhatsApp не отвечает. Человек производил хорошее
A8: впечатление не хотелось бы думать о нем что то дурное. Но если не найду, придется
A9: объявить его в розыск.
A10: Огромная просьба если вы его знаете дайте мне знать где он что с ним
A11: Заранее огромное спасибо за внимание!!!
B13: Дата: | C13: =Дог.!P11 -> 45982
D14: Зинченко М. А.
H15: (подпись)
A19: ПИСЬМО ДЛЯ РОДСТВЕННИКОВ И ДРУЗЕЙ № 2
A20: Добрый день. Меня зовут | E20: =Дог.!A14 -> Зинченко Михаил Александрович | I20: Я занимаюсь
A21: прокатом строительного оборудования и инструмента.
A22: Заранее приношу свои извинения за беспокойство, хотел у Вас спросить - знаком ли Вам
A23: гражданин Кыргызской Республики – | F23: =Дог.!A18 -> {{CLIENT_FULLNAME}}
A24: =Дог.!A23 -> ХХХХХ | C24: года рождения?
A25: Дело в том, что я ищу его родственников или знакомых, в связи с тем, что он уже более
A26: недели не отвечает на телефонные звонки и сообщения в WhatsApp.
A27: =F23 -> {{CLIENT_FULLNAME}} | F27: всегда производил впечатление порядочного,
A28: честного и достойного человека - не хотелось бы допускать о нем каких-то негативных
A29: мыслей. Он неоднократно брал у меня в аренду оборудование и к нему ни разу не
A30: возникало никаких претензий или нареканий.
A31: Однако | C31: ='Пр №1'!J21 -> 45982 | E31: между мной и гражданином Кыргызской Республики
A32: =A27 -> {{CLIENT_FULLNAME}} | G32: =A24 -> ХХХХХ | H32: года рождения был
A33: заключён официальный договор аренды оборудования. Им было взято на прокат
A34: следующее оборудование:
A35: Взятое | C35: =C31 -> 45982 | E35: года строительное оборудование до сих пор не сдано.
A36: На сегодняшний день задолженность по арендной плате составляет | I36: ='Акт расч'!P48 -> -3000
A37: =[2]!ЧислоПрописьюВалюта(I36,2) -> #NAME?
A38: составлен соответствующий Акт расчета. Он брал оборудование на несколько дней, но
A39: пропал и не выходил на связь.
A40: Я сдаю строительное оборудование в прокат людям чтобы они могли произвести
A41: различные строительно- монтажные работы и тем самым помогаю им чтобы они могли
A42: зарабатывать и обеспечивать свои семьи, или произвести у себя дома ремонт не неся при
A43: этом дополнительных ощутимых затрат на приобретение дорогостоящих строительных
A44: инструментов и оборудования, которые нужны на кратковременный период проведения
A45: работ и в дальнейшем использоваться не будут.
...

Sheet В милицию
A2: И Н Ф О Р М А Ц И Я О З А Я В И Т Е Л Е:
A4: 1 | B4: Ф.И.О. | F4: =Дог.!A14 -> Зинченко Михаил Александрович
A5: 2 | B5: Дата рождения | F5: 39073
A6: 3 | B6: Место рождения | F6: г. Бишкек
A7: 4 | B7: Гражданство | F7: Кыргызское
A8: 5 | B8: Номер, серия и дата выдачи паспорта | F8: № ID 3219844 МКК 218011 от 12.02.2023
A9: 6 | B9: Пин \ ИНН | F9: 22212200650516
A10: 7 | B10: Адрес по прописке | F10: ул. Ялтинская д 56 \1
A11: 8 | B11: Фактический адрес проживания | F11: ул. Ялтинская д 56 \1
A12: 9 | B12: № раб. телефона | F12: 0 555 147 688
A13: 10 | B13: № дом. телефона
A14: 11 | B14: № моб. телефона | F14: 0 706 147 688
A15: 12 | B15: Место работы | F15: Индивидуальный предприниматель
A16: 13 | B16: Должность | F16: Руководитель проката
A17: 14 | B17: Образование | F17: Среднее
A18: 15 | B18: Семейное положение | F18: Нет
A19: 16 | B19: Примечание (обращался ли ранее с заявлением об этом совершённом или готовящемся преступлении\проступке в другой правоохранительный орган, если да то когда и в какой орган): | F19: нет
A20: 17 | B20: Приложение (имеются вещественные доказательства. аудио-видео запись происшествия, документы и другие, относящиеся к преступлению\проступку материалы):
A21: 18 | B21: Дополнения (любые имеющиеся дополнения в части информации о заявителе):
A22: Заявление и личные данные с моих слов напечатаны (написаны) верно, мной
A23: прочитаны (написаны, напечатаны собственноручно) -нужное подчеркнуть
D25: Подпись заявителя
H26: (подпись)
A27: «____» ___________ 2019 г. | G27: «____» час. «____»мин.
A29: Заявление принял:_______________________________________________________
A30: ________________________________________________________
A31: (должность, фамилия, инициалы, подпись)
A33: Выдан талон-уведомление №_______________________________________
G37: Начальнику УВД Свердловского
G38: района города Бишкек
G39: Полковнику милиции
G40: Тагаеву А.Г.
G41: ОТ КОГО: Зинченко
G42: Михаила Александровича
A46: ЗАЯВЛЕНИЕ
A47: о совершённом или готовящемся преступлении/проступке
B49: Я, | C49: =F4 -> Зинченко Михаил Александрович | G49: прошу привлечь к уголовной
A50: ответственности | D50: =Дог.!A18 -> {{CLIENT_FULLNAME}} | H50: год рож. | I50: =Дог.!A23 -> ХХХХХ
A51: за то, что он | C51: ='Пр №1'!J21 -> 45982 | E51: года примерно в | G51: ='Пр №1'!J20 -> 45982.791 | H51: часов находясь в офисе
A52: по прокату строительного инструмента расположенного по адресу | I52: =Дог.!B13 -> г. Бишкек
...

Sheet Фразы для Ватсапа
B1: ЛЕРМОНТОВА 68 | C1: КЫРГЫЗ ПРОКАТ | D1: ПИШПЕК ПРОКАТ
B2: *ОПОВЕЩЕНИЕ* | C2: *ОПОВЕЩЕНИЕ* | D2: *ОПОВЕЩЕНИЕ*
B3: *НАПОМИНАНИЕ* | C3: *НАПОМИНАНИЕ* | D3: *НАПОМИНАНИЕ*
B4: *Доброе время суток* | C4: *Доброе время суток* | D4: *Доброе время суток*
B5: Вас беспокоят с пункта проката строительного оборудования *LEVEL* | C5: Вас беспокоят с пункта проката строительного оборудования *КЫРГЫЗПРОКАТ* | D5: Вас беспокоят с пункта проката строительного оборудования *ПИШПЕК ПРОКАТ*
B6: По адресу: с. Лебединовка ул. Лермонтова дом № 68 | C6: По адресу: Куттубаева 26а/3 | D6: По адресу: ВОРОВСКОГО 1\3
B7: Вы брали у нас: ----- | C7: Вы брали у нас: ------ | D7: Вы брали у нас: ------
B8: Информирую Вас что депозит закончился | C8: Информирую Вас, что депозит закончился | D8: Информирую Вас, что депозит закончился
B9: У Вас образовалась задолженность: ------- | C9: У Вас образовалась задолженность: ------ | D9: У Вас образовалась задолженность:------
B10: *РАБОЧИЙ ГРАФИК* | C10: *РАБОЧИЙ ГРАФИК* | D10: *РАБОЧИЙ ГРАФИК*
B11: С понедельника по пятницу | C11: С понедельника по пятницу | D11: С понедельника по пятницу
B12: *С 8:00 до 19:00*(семь часов вечера) | C12: *С 8:00 до 19:00*(семь часов вечера) | D12: *С 8:00 до 19:00*(семь часов вечера)
... B19: каждый день | C19: каждый день | D19: каждый день
A20: ФРАЗЫ ДЛЯ WhatsApp
B21: Вежливое общение | C21: Не большой наезд | D21: Наезд
A22: 1 | B22: Сколько Вы еще планируете пользоваться оборудованием? | C22: Обещали приехать сегодня, ----, ждём Вас. | D22: Когда Вы сдадите оборудование и оплатите арендную плату?
A23: 2 | B23: Когда Вы планируете сдать оборудование? | C23: Вы обещали приехать ---- и оплатить, но не приехали? | D23: Когда Вы оплатите арендную плату?
A24: 3 | B24: Назовите, пожалуйста дату, когда Вы планируете сдать оборудование. | C24: Вы обещали приехать -----, но не приехали? | D24: Когда Вы сдадите оборудование?
